Workbook

Sheet SUMMARY 
A2: DAILY TRANSACTIONS GROUP B
B3: NAME OF COMPANY | C3: AED | D3: USD | E3: EURO | F3: REMARKS | G3: AED CREDIT | H3: AED DEBIT | I3: USD CREDIT | J3: USD DEBIT | K3: EUR CREDIT | L3: EUR DEBIT
C4: ='HEDGES MSQ AED '!E100 -> 0 | D4: ='HEDGES MSQ USD'!E100 -> 0 | E4: ='HEDGES MSQ EURO'!E100 -> 0 | F4: CLOSED
A5: 1A | B5: HEDGES GOODS FAB | C5: ='HEDGES FAB AED '!E100 -> 317.31 | D5: ='HEDGES FAB USD'!E100 -> 124.89
F6: CLOSED
A7: 2A | B7: RHINE MSQ | C7: 0 | F7: NA
A8: 2B | B8: RHINE ENBD | C8: 2705.9 | D8: 0 | F8: KYC ISSUE
A9: 2C | B9: RHINE | C9: -4.31 | D9: 17.86 | E9: 0
A10: 2D | B10: RHINE SIB | C10: 142.71 | D10: 0 | F10: KYC ISSUE
A11: 2E | B11: RHINE AJMAN | C11: -4538 | D11: 85.91 | F11: NA
A12: 2F | B12: RHINE ADIB | C12: 895.61 | D12: 0
A14: 1A | B14: RHINE MULTY NBF | C14: ='RHINE MULTY NBF AED'!E100 -> 1091.95
A16: 3A | B16: CARNIFY ENBD | C16: ='CARNIFY ENBD AED'!E326 -> 616.13 | D16: ='CARNIFY ENBD USD '!E100 -> 1.84
A17: 3B | B17: CARNIFY ADIB | C17: ='CARNIFY ADIB AED '!E325 -> 1311.97 | D17: ='CARNIFY ADIB USD'!E100 -> 787.62 | F17: KYC ISSUE
A18: 3C | B18: CARNIFY EIB | C18: ='CARNIFY EIB AED'!E326 -> 128.21
A20: 4A | B20: RED STONE WIO | C20: ='RED STONE WIO AED '!E397 -> -400.002 | D20: ='RED STONE WIO USD'!E143 -> 0.27 | E20: ='RED STONE WIO EUR'!E110 -> 0.42 | M20: CAN'T TRF
A21: 4B | B21: RED STONE ADIB | C21: ='RED STONE ADIB AED '!E100 -> 111.63 | D21: ='RED STONE ADIB USD'!E110 -> 0 | E21: ='RED STONE ADIB EUR'!E110 -> 0 | M21: ACTIVE BUT TL EXPIRED
A23: 5A | B23: IDEA GROVE ADIB | C23: ='IDEA GROVE ADIB AED'!E100 -> 322 | D23: ='IDEA GROVE ADIB USD'!E100 -> 2 | E23: ='IDEA GROVE ADIB EURO'!E100 -> 5
A24: 5B | B24: IDEA GROVE EIB | C24: ='IDEA GROVE EIB AED'!E352 -> 83.82 | D24: =500+100-514.56-54.82-25.73-2.74+89850-11.23-224.62-100-60000-28000-1360+9840-54.82-2.74-9938 -> 0.74 | M24: ISSUE
A25: 5C | B25: IDEA GROVE RAK | C25: ='IDEA GROVE RAK AED'!E100 -> 9250.35 | M25: CHQ
A26: 5D | B26: IDEA GROVE SIB | C26: ='IDEA GROVE SIB AED'!E100 -> 187.98
A28: 6A | B28: AGNIRA WIO | C28: ='AGINRA WIO AED'!E203 -> 1758.71 | D28: ='AGNIRA WIO USD'!E100 -> 0.75 | F28: ASHISH JI
A29: 6B | B29: AGNIRA EIB | C29: ='AGINRA EIB AED '!E131 -> 733.15 | F29: ASHISH JI
A31: 7A | B31: SILVER STONE WIO A/C | C31: ='SILVER STONE WIO AED'!E345 -> 1815.435 | D31: ='SILVER STONE WIO USD'!E99 -> 0 | E31: ='SILVER STONE WIO EUR'!E63 -> 0
A32: 7B | B32: SILVER STONE ADIB A/C | C32: ='SILVER STONE ADIB AED'!E63 -> 108.53 | D32: ='SILVER STONE ADIB USD'!E63 -> 0.35 | E32: ='SILVER STONE ADIB EUR'!E63 -> 0
A33: 7C | B33: SILVER STONE MSQ A/C | C33: ='SILVER STONE MSQ AED '!E100 -> 0
A34: 7D | B34: SILVER STONE ENBD A/C | C34: ='SILVER STONE ENBD AED '!E100 -> 524299.95
A36: 8A | B36: M J S STAR NBF | C36: ='M J S STAR NBF AED '!E100 -> 0.02 | D36: ='M J S STAR NBF USD'!E100 -> 0.01
A37: 8B | B37: M J S STAR RAK | C37: ='M J S STAR RAK AED '!E100 -> 1798.2 | D37: ='M J S STAR RAK USD'!E100 -> 1000 | F37: ONLINE NOT ACTIVATED
A38: 8C | B38: M J S STAR EIB | C38: ='MJS STAR EIB AED'!E237 -> 775.95 | F38: NA
A39: 8D | B39: M J S STAR SIB | C39: ='MJS STAR SIB AED'!E100 -> 1093.16 | D39: ='MJS STAR SIB USD'!E100 -> 286.99
A40: 8E | B40: M J S STAR UBL | C40: 0 | D40: 0
A42: 9A | B42: CAPSLOCK FAB | C42: ='CAPS LOCK FAB AED '!E363 -> 232.64 | D42: ='CAPS LOCK FAB USD'!E100 -> 1.6
A43: 9B | B43: CAPSLOCK SIB | C43: ='CAPSLOCK SIB AED'!E140 -> 113.95 | D43: ='CAPSLOCK SIB USD'!E100 -> -8.58
A44: 9C | B44: CAPSLOCK WIO | C44: ='CAPS LOCK WIO AED '!E100 -> 1455
A46: 10A | B46: FUTURE BRIDGE GT MSQ | C46: ='FUTURE BRIDGE MSQ AED'!E100 -> 1640.95 | D46: 0
A48: 11A | B48: GOLDENOVA GENEAL TRAD. RAK | C48: ='GOLDENOVA RAK AED'!E100 -> 5.6843419e-13
A50: 12A | B50: SHRIJI INTERNATIONAL EIB | C50: ='SHRIJI INT EIB AED'!E244 -> 1191.9 | D50: 0
A52: 13A | B52: ORBIT PLUS SIB | C52: ='ORBIT PLUS SIB'!E209 -> 95.08
A53: 13B | B53: ORBIT PLUS MSQ | C53: 0
...

Sheet MJS STAR EIB AED
A1: M J S STAR
A2: EIB AED
A3: DATE | B3: PARTICULAR | C3: DEPOSIT | D3: WITHDRAWAL | E3: BALANCE
B4: OPENING BALANCE | E4: -131.25
A5: 29-08-2025 | B5: FUND RECD FROM ROYAL EN EM ENBD AED | C5: 410257 | E5: =E4+C5-D5 -> 410125.75
A6: 29-08-2025 | B6: TT TRF TO Meteor Balanced Portfolio USD 108325@3.692 | D6: 399935.9 | E6: =E5+C6-D6 -> 10189.85
A7: 02.09.2025 | B7: BANK CHARGES | D7: 125 | E7: =E6+C7-D7 -> 10064.85
A8: 02.09.2025 | B8: BANK CHARGES | D8: 6.25 | E8: =E7+C8-D8 -> 10058.6
A9: 18.09.2025 | B9: CHEQUE DEPOSIT Y A X A TRADING LLC | C9: 915750 | E9: =E8+C9-D9 -> 925808.6
A10: 18.09.2025 | B10: TT TRF TO BLACK PEPPER ADIB AED | D10: 496857 | E10: =E9+C10-D10 -> 428951.6
A11: 18.09.2025 | B11: BANK CHARGES | D11: 21 | E11: =E10+C11-D11 -> 428930.6
A12: 18.09.2025 | B12: TT TRF TO BLACK PEPPER ADIB AED | D12: 426851 | E12: =E11+C12-D12 -> 2079.6
A13: 18.09.2025 | B13: BANK CHARGES | D13: 21 | E13: =E12+C13-D13 -> 2058.6
A14: 19.09.2025 | B14: CHEQUE DEPOSIT (ROHIT MEHTA) | C14: 2307 | E14: =E13+C14-D14 -> 4365.6
A15: 20.09.2025 | B15: FUND RECD FROM ALTARIQ ALMETHALI HEAVY EQUIPMENT | C15: 850000 | E15: =E14+C15-D15 -> 854365.6
A16: 20.09.2025 | B16: TT TRF FROM M J STAR TO BLACK PEPPER ADIB | D16: 598671 | E16: =E15+C16-D16 -> 255694.6
A17: 20.09.2025 | B17: BANK CHARGES | D17: 21 | E17: =E16+C17-D17 -> 255673.6
A18: 20.09.2025 | B18: TT TRF FROM M J STAR TO COMIDA UBL | D18: 253104 | E18: =E17+C18-D18 -> 2569.6
A19: 20.09.2025 | B19: BANK CHARGES | D19: 21 | E19: =E18+C19-D19 -> 2548.6
A20: 20.09.2025 | B20: BANK CHARGES | D20: 4.2 | E20: =E19+C20-D20 -> 2544.4
A21: 22.09.2025 | B21: FUND RECD FROM SILVER CROSS EQUIPMENT | C21: 579640 | E21: =E20+C21-D21 -> 582184.4
A22: 22.09.2025 | B22: TT TRF FROM MJS STAR EIB TO CAPS LOCK FAB | D22: 580213 | E22: =E21+C22-D22 -> 1971.4
A23: 22.09.2025 | B23: BANK CHARGES | D23: 21 | E23: =E22+C23-D23 -> 1950.4
A24: 25.09.2025 | B24: CASH DEPOSIT | C24: 224000 | E24: =E23+C24-D24 -> 225950.4
A25: 25.09.2025 | B25: TT TRF TO CAPS LOCK FAB AED | D25: 8201 | E25: =E24+C25-D25 -> 217749.4
A26: 25.09.2025 | B26: BANK CHARGES | D26: 21 | E26: =E25+C26-D26 -> 217728.4
A27: 25.09.2025 | B27: TT TRF TO BLACK PEPPER ADIB AED | D27: 215410 | E27: =E26+C27-D27 -> 2318.4
A28: 25.09.2025 | B28: BANK CHARGES | D28: 21 | E28: =E27+C28-D28 -> 2297.4
A29: 29.09.2025 | B29: CASH DEPOSIT | C29: 101000 | E29: =E28+C29-D29 -> 103297.4
A30: 29.09.2025 | B30: CASH DEPOSIT | C30: 117000 | E30: =E29+C30-D30 -> 220297.4
A31: 29.09.2025 | B31: CASH DEPOSIT | C31: 100000 | E31: =E30+C31-D31 -> 320297.4
A32: 29.09.2025 | B32: TT TRF TO BLACK PEPPER ADIB AED | D32: 319230 | E32: =E31+C32-D32 -> 1067.4
A33: 29.09.2025 | B33: BANK CHARGES | D33: 25.2 | E33: =E32+C33-D33 -> 1042.2
A34: 02.10.2025 | B34: BANK CHARGES | D34: 300 | E34: =E33+C34-D34 -> 742.2
A35: 02.10.2025 | B35: BANK CHARGES | D35: 125 | E35: =E34+C35-D35 -> 617.2
A36: 02.10.2025 | B36: BANK CHARGES | D36: 15 | E36: =E35+C36-D36 -> 602.2
A37: 02.10.2025 | B37: BANK CHARGES | D37: 6.25 | E37: =E36+C37-D37 -> 595.95
A38: 09.10.2025 | B38: CHEQUE RECD FROM AFFORDABLES FASHION LLC | C38: 100000 | E38: =E37+C38-D38 -> 100595.95
A39: 09.10.2025 | B39: TT TRF TO BLACK PEPPER NBF AED | D39: 99687 | E39: =E38+C39-D39 -> 908.95
A40: 09.10.2025 | B40: BANK CHARGES | D40: 22.05 | E40: =E39+C40-D40 -> 886.9
...

Sheet RHINE MULTY NBF AED
A1: M J S STAR
A2: EIB AED
A3: DATE | B3: PARTICULAR | C3: DEPOSIT | D3: WITHDRAWAL | E3: BALANCE
E4: 0
A5: 28.04.2026 | B5: FUND RECD FROM | C5: 105323 | E5: =E4+C5-D5 -> 105323
A6: 28.04.2026 | B6: TT TRF TO PINNACLE GR NBF AED | D6: 104230 | E6: =E5+C6-D6 -> 1093
A7: 28.04.2026 | B7: BANK CHARGES | D7: 1.05 | E7: =E6+C7-D7 -> 1091.95
E8: =E7+C8-D8 -> 1091.95
E9: =E8+C9-D9 -> 1091.95
E10: =E9+C10-D10 -> 1091.95
E11: =E10+C11-D11 -> 1091.95
E12: =E11+C12-D12 -> 1091.95
E13: =E12+C13-D13 -> 1091.95
E14: =E13+C14-D14 -> 1091.95
E15: =E14+C15-D15 -> 1091.95
E16: =E15+C16-D16 -> 1091.95
E17: =E16+C17-D17 -> 1091.95
E18: =E17+C18-D18 -> 1091.95
E19: =E18+C19-D19 -> 1091.95
... E100: =E99+C100-D100 -> 1091.95

Sheet MJS STAR SIB AED
A1: M J S STAR
A2: SIB AED
A3: DATE | B3: PARTICULAR | C3: DEPOSIT | D3: WITHDRAWAL | E3: BALANCE
B4: OPENING BALANCE | E4: 1948.5
A5: 25.02.2026 | B5: FUND RECD FROM CAPS LOCK FAB AED | C5: 11252 | E5: =E4+C5-D5 -> 13200.5
A6: 25.02.2026 | B6: TT TRF TO CRIF GULF DWC | D6: 11200 | E6: =E5+C6-D6 -> 2000.5
A7: 25.02.2026 | B7: BANK CHARGES | D7: 0.5 | E7: =E6+C7-D7 -> 2000
A8: 02.03.2026 | B8: BANK CHARGES | D8: 425.25 | E8: =E7+C8-D8 -> 1574.75
A9: 02.03.2026 | B9: AED TO USD | D9: 369.14 | E9: =E8+C9-D9 -> 1205.61
A10: 11.03.2026 | B10: FUND RECD FROM PINNACLE GR NBF AED | C10: 612582 | E10: =E9+C10-D10 -> 613787.61
A11: 11.03.2026 | B11: FUND RECD FROM PINNACLE GR NBF AED | C11: 490231 | E11: =E10+C11-D11 -> 1104018.6
A12: 11.03.2026 | B12: FUND RECD FROM PINNACLE GR NBF AED | C12: 1013 | E12: =E11+C12-D12 -> 1105031.6
A13: 11.03.2026 | B13: TT TRF TO METEOR SMB (USD 300010) | D13: 1104036.8 | E13: =E12+C13-D13 -> 994.81
A14: 30.03.2026 | B14: CASH DEPOSIT | C14: 200000 | E14: =E13+C14-D14 -> 200994.81
A15: 30.03.2026 | B15: TT TRF TO ORBIT PLUS WIO AED | D15: 200315 | E15: =E14+C15-D15 -> 679.81
A16: 30.03.2026 | B16: BANK CHARGES | D16: 1.05 | E16: =E15+C16-D16 -> 678.76
A17: 30.03.2026 | B17: FUND RECD FROM INVESTRADE PTE | C17: 998895 | E17: =E16+C17-D17 -> 999573.76
A18: 30.03.2026 | B18: TT TRF TO BLACK PEPPER GT SIB AED | D18: 999010 | E18: =E17+C18-D18 -> 563.76
A19: 01.04.2026 | B19: BANK CHARGES | D19: 425.25 | E19: =E18+C19-D19 -> 138.51
A20: 02.04.2026 | B20: CASH DEPOSIT | C20: 200000 | E20: =E19+C20-D20 -> 200138.51
A21: 02.04.2026 | B21: TT TRF TO BLACK PEPPER GT SIB AED | D21: 199868 | E21: =E20+C21-D21 -> 270.51
A22: 06.04.2026 | B22: CASH DEPOSIT | C22: 200000 | E22: =E21+C22-D22 -> 200270.51
A23: 07.04.2026 | B23: TT TRF TO BLACK PEPPER GT SIB AED | D23: 199500 | E23: =E22+C23-D23 -> 770.51
A24: 10.04.2026 | B24: CASH DEPOSIT | C24: 200000 | E24: =E23+C24-D24 -> 200770.51
A25: 10.04.2026 | B25: TT TRF TO BLACK PEPPER NBF AED | D25: 199686 | E25: =E24+C25-D25 -> 1084.51
A26: 10.04.2026 | B26: BANK CHARGES | D26: 1.05 | E26: =E25+C26-D26 -> 1083.46
A27: 13.04.2026 | B27: FUND RECD FROM PINNACLE GR NBF AED | C27: 622130 | E27: =E26+C27-D27 -> 623213.46
A28: 13.04.2026 | B28: FUND RECD FROM AMINEX SIB AED | C28: 14880 | E28: =E27+C28-D28 -> 638093.46
A29: 13.04.2026 | B29: FUND RECD FROM ROYAL EN EM NBF AED | C29: 100325 | E29: =E28+C29-D29 -> 738418.46
A30: 13.04.2026 | B30: TT TRF TO METEOR SMB (USD 200000) | D30: 736000 | E30: =E29+C30-D30 -> 2418.46
A31: 15.04.206 | B31: CASH DEPOSIT | C31: 200000 | E31: =E30+C31-D31 -> 202418.46
A32: 15.04.206 | B32: TT TRF TO CROSSFIT SIB AED | D32: 201560 | E32: =E31+C32-D32 -> 858.46
A33: 17.04.2026 | B33: CASH DEPOSIT | C33: 200000 | E33: =E32+C33-D33 -> 200858.46
A34: 17.04.2026 | B34: FUND RECD FROM AMINEX SIB AED | C34: 217569 | E34: =E33+C34-D34 -> 418427.46
A35: 17.04.2026 | B35: TT TRF TO BLACK PEPPER GT NBF | D35: 417880 | E35: =E34+C35-D35 -> 547.46
A36: 17.04.2026 | B36: BANK CHARGES | D36: 1.05 | E36: =E35+C36-D36 -> 546.41
A37: 18.04.2026 | B37: CASH DEPOSIT | C37: 98440 | E37: =E36+C37-D37 -> 98986.41
A38: 18.04.2026 | B38: TT TRF TO COMIDA GOODS NBF AED | D38: 98750 | E38: =E37+C38-D38 -> 236.41
A39: 21.04.2026 | B39: FUND RECD FROM AMINEX SIB AED | C39: 364023 | E39: =E38+C39-D39 -> 364259.41
A40: 21.04.2026 | B40: FUND RECD FROM BLACK PEPPER GT NBF | C40: 4500 | E40: =E39+C40-D40 -> 368759.41
...

Sheet MJS STAR SIB USD
A1: M J S STAR
A2: SIB USD
A3: DATE | B3: PARTICULAR | C3: DEPOSIT | D3: WITHDRAWAL | E3: BALANCE
B4: OPENING BALANCE | E4: 0
A5: 02.03.2026 | B5: AED TO USD | C5: 100 | E5: =E4+C5-D5 -> 100
A6: 02.03.2026 | B6: BANK CHARGES | D6: 10.01 | E6: =E5+C6-D6 -> 89.99
A7: 13.03.2026 | B7: FUND RECD FROM ROYAL EN EM | C7: 200200 | E7: =E6+C7-D7 -> 200289.99
A8: 13.03.2026 | B8: TT TRF TO METEOR | D8: 200003 | E8: =E7+C8-D8 -> 286.99
E9: =E8+C9-D9 -> 286.99
E10: =E9+C10-D10 -> 286.99
E11: =E10+C11-D11 -> 286.99
E12: =E11+C12-D12 -> 286.99
E13: =E12+C13-D13 -> 286.99
E14: =E13+C14-D14 -> 286.99
E15: =E14+C15-D15 -> 286.99
E16: =E15+C16-D16 -> 286.99
E17: =E16+C17-D17 -> 286.99
E18: =E17+C18-D18 -> 286.99
E19: =E18+C19-D19 -> 286.99
E20: =E19+C20-D20 -> 286.99
... E100: =E99+C100-D100 -> 286.99

Sheet GRENEW FZE NBF
A1: GRENEW FZE NBF AED
E4: =C4 -> 0
A5: 07.11.2025 | B5: CASH DEPOSIT | C5: 7810 | E5: =E4+C5-D5 -> 7810
A6: 14.11.2025 | B6: FUND RECD FREOM MIDDLE EAST COMPUTERS SYSTEM | C6: 879.75 | E6: =E5+C6-D6 -> 8689.75
A7: 27.11.2025 | B7: FUND RECD FROM PINNACLE GR NBF | C7: 40800 | E7: =E6+C7-D7 -> 49489.75
A8: 27.11.2025 | B8: TT TRF TO Alhayat Aljadeeda Electro | D8: 27615 | E8: =E7+C8-D8 -> 21874.75
A9: 29.11.2025 | B9: CHQ PAID | D9: 13125 | E9: =E8+C9-D9 -> 8749.75
A10: 29.11.2025 | B10: BANK CHARGES | D10: 17.5 | E10: =E9+C10-D10 -> 8732.25
A11: 29.11.2025 | B11: BANK CHARGES | D11: 350 | E11: =E10+C11-D11 -> 8382.25
A12: 05.12.2025 | B12: TT TRF TO SOMNATH NEERAJ SRIVASTAV AXIS INR 150K | D12: 6210 | E12: =E11+C12-D12 -> 2172.25
A13: 09.12.2025 | B13: FUND RECD FROM PINNACLE GR NBF | C13: 71000 | E13: =E12+C13-D13 -> 73172.25
E14: =E13+C14-D14 -> 73172.25
E15: =E14+C15-D15 -> 73172.25
E16: =E15+C16-D16 -> 73172.25
E17: =E16+C17-D17 -> 73172.25
E18: =E17+C18-D18 -> 73172.25
E19: =E18+C19-D19 -> 73172.25
E20: =E19+C20-D20 -> 73172.25
E21: =E20+C21-D21 -> 73172.25
E22: =E21+C22-D22 -> 73172.25
E23: =E22+C23-D23 -> 73172.25
E24: =E23+C24-D24 -> 73172.25
E25: =E24+C25-D25 -> 73172.25
... E27: =E26+C27-D27 -> 73172.25
E28: =E27+C28-D28 -> 73172.25 | G28: =+E28-1138.34 -> 72033.91
E29: =E28+C29-D29 -> 73172.25
E30: =E29+C30-D30 -> 73172.25
E31: =E30+C31-D31 -> 73172.25
E32: =E31+C32-D32 -> 73172.25
E33: =E32+C33-D33 -> 73172.25
E34: =E33+C34-D34 -> 73172.25
E35: =E34+C35-D35 -> 73172.25
E36: =E35+C36-D36 -> 73172.25
E37: =E36+C37-D37 -> 73172.25
E38: =E37+C38-D38 -> 73172.25
E39: =E38+C39-D39 -> 73172.25
E40: =E39+C40-D40 -> 73172.25
... E210: =E209+C210-D210 -> 73172.25

Sheet SWIFT BRIDGE SIB AED
A1: SWIFT BRIDGE SIB AED
A4: 31-07-2025 | B4: OPENING BALANCE | C4: 4825.75 | E4: =C4 -> 4825.75
A5: 31-07-2025 | B5: BANK CHARGES | D5: 315 | E5: =E4+C5-D5 -> 4510.75
A6: 30-08-2025 | B6: BANK CHARGES | D6: 320.25 | E6: =E5+C6-D6 -> 4190.5
A7: 17.09.2025 | B7: FUND RECD FROM Y A X A TRADING LLC AED | C7: 499723 | E7: =E6+C7-D7 -> 503913.5
A8: 17.09.2025 | B8: TT TRF TO SHRIJI INT EIB AED | D8: 498521 | E8: =E7+C8-D8 -> 5392.5
A9: 17.09.2025 | B9: BANK CHARGES | D9: 1.05 | E9: =E8+C9-D9 -> 5391.45
A10: 30.09.2025 | B10: BANK CHARGES | D10: 320.25 | E10: =E9+C10-D10 -> 5071.2
A11: 01.10.2025 | B11: FUND RECD FROM SILVER CROSS EQUIPMENT TRADING | C11: 751070 | E11: =E10+C11-D11 -> 756141.2
A12: 01.10.2025 | B12: TT TRF TO SHRIJI INT EIB AED | D12: 499683 | E12: =E11+C12-D12 -> 256458.2
A13: 01.10.2025 | B13: BANK CHARGES | D13: 1.05 | E13: =E12+C13-D13 -> 256457.15
A14: 02.10.2025 | B14: TT TRF TO SHRIJI INT EIB AED | D14: 255760 | E14: =E13+C14-D14 -> 697.15
A15: 02.10.2025 | B15: BANK CHARGES | D15: 1.058 | E15: =E14+C15-D15 -> 696.092
A16: 11.10.2025 | B16: BANK CHARGES | D16: 210 | E16: =E15+C16-D16 -> 486.092
A17: 17.10.2025 | B17: FUND RECD FROM CAPS LOCK FAB | C17: 7236 | E17: =E16+C17-D17 -> 7722.092
A18: 17.10.2025 | B18: TT TRF TO LOVEDEEP SINGH MSQ AED | D18: 5000 | E18: =E17+C18-D18 -> 2722.092
A19: 17.10.2025 | B19: BANK CHARGES | D19: 0.5 | E19: =E18+C19-D19 -> 2721.592
A20: 24.10.2025 | B20: FUND RECD FROM TAJ INTERNATIONAL (INDIA) | C20: 67996.14 | E20: =E19+C20-D20 -> 70717.732
A21: 24.10.2025 | B21: TT TRF TO SHRIJI INT EIB AED | D21: 68960 | E21: =E20+C21-D21 -> 1757.732
A22: 24.10.2025 | B22: BANK CHARGES | D22: 1.05 | E22: =E21+C22-D22 -> 1756.682
A23: 28.10.2025 | B23: CASH DEPOSIT | C23: 225000 | E23: =E22+C23-D23 -> 226756.68
A24: 28.10.2025 | B24: TT TRF TO SHRIJI INT EIB AED | D24: 225643 | E24: =E23+C24-D24 -> 1113.682
A25: 28.10.2025 | B25: BANK CHARGES | D25: 1.05 | E25: =E24+C25-D25 -> 1112.632
A26: 31.10.2025 | B26: CASH DEPOSIT | C26: 225000 | E26: =E25+C26-D26 -> 226112.63
A27: 31.10.2025 | B27: TT TRF TO SHRIJI INT EIB AED | D27: 224968 | E27: =E26+C27-D27 -> 1144.632
A28: 31.10.2025 | B28: BANK CHARGES | D28: 1.05 | E28: =E27+C28-D28 -> 1143.582 | G28: =+E28-1138.34 -> 5.242
A29: 31.10.2025 | B29: BANK CHARGES | D29: 5.24 | E29: =E28+C29-D29 -> 1138.342
A30: 31.10.2025 | B30: BANK CHARGES | D30: 315 | E30: =E29+C30-D30 -> 823.342
A31: 11.12.2025 | B31: CASH DEPOSIT | C31: 125000 | E31: =E30+C31-D31 -> 125823.34
A32: 11.12.2025 | B32: CASH DEPOSIT | C32: 77000 | E32: =E31+C32-D32 -> 202823.34
A33: 11.12.2025 | B33: TT TRF TO AMINEX SIB | D33: 201569 | E33: =E32+C33-D33 -> 1254.342
A34: 11.12.2025 | B34: BANK CHARGES | D34: 477.75 | E34: =E33+C34-D34 -> 776.592 | G34: =1254.34-776.59 -> 477.75
A35: 12.12.2025 | B35: CASH DEPOSIT | C35: 250000 | E35: =E34+C35-D35 -> 250776.59
A36: 12.12.2025 | B36: TT TRF TO AMINEX SIB | D36: 249804 | E36: =E35+C36-D36 -> 972.592
A37: 16.12.2025 | B37: CASH DEPOSIT | C37: =175000+24500+50000 -> 249500 | E37: =E36+C37-D37 -> 250472.59
A38: 16.12.2025 | B38: TT TRF TO SHRIJI INT EIB AED | D38: 248968 | E38: =E37+C38-D38 -> 1504.592
A39: 16.12.2025 | B39: BANK CHARGES | D39: 1.05 | E39: =E38+C39-D39 -> 1503.542
A40: 17.12.2025 | B40: CASH DEPOSIT | C40: 300000 | E40: =E39+C40-D40 -> 301503.54
A41: 17.12.2025 | B41: TT TRF TO AMINEX SIB | D41: 300428 | E41: =E40+C41-D41 -> 1075.542
A42: 19.12.2025 | B42: CASH DEPOSIT | C42: 300000 | E42: =E41+C42-D42 -> 301075.54
...

Sheet SWIFT BRIDGE ADIB AED
A1: SWIFT BRIDGE ADIB AED
A4: 23.04.2026 | B4: FUND RECD FROM BLACK PEPPER NBF AED | C4: 12300 | E4: =C4 -> 12300 | G4: A/C OPENED
A5: 23.04.2026 | B5: AED TO USD | D5: 6000 | E5: =E4+C5-D5 -> 6300
A6: 29.04.2026 | B6: USD TO AED | C6: 5816 | E6: =E5+C6-D6 -> 12116
A7: 29.04.2026 | B7: TT TRF TO SWIFT BRIDGE SIB AED | D7: 11200 | E7: =E6+C7-D7 -> 916
A8: 29.04.2026 | B8: BANK CHARGES | D8: 15.75 | E8: =E7+C8-D8 -> 900.25
E9: =E8+C9-D9 -> 900.25
E10: =E9+C10-D10 -> 900.25
E11: =E10+C11-D11 -> 900.25
E12: =E11+C12-D12 -> 900.25
E13: =E12+C13-D13 -> 900.25
E14: =E13+C14-D14 -> 900.25
E15: =E14+C15-D15 -> 900.25
E16: =E15+C16-D16 -> 900.25
E17: =E16+C17-D17 -> 900.25
E18: =E17+C18-D18 -> 900.25
E19: =E18+C19-D19 -> 900.25
E20: =E19+C20-D20 -> 900.25
... E210: =E209+C210-D210 -> 900.25

Sheet SWIFT BRIDGE ADIB USD
A1: SWIFT BRIDGE ADIB USD
A4: 23.04.2026 | B4: AED TO USD | C4: 1617.47 | E4: =C4 -> 1617.47
A5: 29.04.2026 | B5: USD TO AED | D5: 1600 | E5: =E4+C5-D5 -> 17.47
E6: =E5+C6-D6 -> 17.47
E7: =E6+C7-D7 -> 17.47
E8: =E7+C8-D8 -> 17.47
E9: =E8+C9-D9 -> 17.47
E10: =E9+C10-D10 -> 17.47
E11: =E10+C11-D11 -> 17.47
E12: =E11+C12-D12 -> 17.47
E13: =E12+C13-D13 -> 17.47
E14: =E13+C14-D14 -> 17.47
E15: =E14+C15-D15 -> 17.47
E16: =E15+C16-D16 -> 17.47
E17: =E16+C17-D17 -> 17.47
... E210: =E209+C210-D210 -> 17.47

Sheet SWIFT BRIDGE SIB USD
A1: SWIFT BRIDGE SIB USD
A4: 21.04.2026 | B4: FUND RECD FROM BILLION RIGHT | C4: 450494.68 | E4: =C4 -> 450494.68
A5: 21.04.2026 | B5: TT TRF TO TB ORIGINATIONS | D5: 200000 | E5: =E4+C5-D5 -> 250494.68
A6: 21.04.2026 | B6: TT TRF TO TB ORIGINATIONS | D6: 250000 | E6: =E5+C6-D6 -> 494.68
A7: 21.04.2026 | B7: BANK CHARGES | D7: 55.8 | E7: =E6+C7-D7 -> 438.88
E8: =E7+C8-D8 -> 438.88
E9: =E8+C9-D9 -> 438.88
E10: =E9+C10-D10 -> 438.88
E11: =E10+C11-D11 -> 438.88
E12: =E11+C12-D12 -> 438.88
E13: =E12+C13-D13 -> 438.88
E14: =E13+C14-D14 -> 438.88
E15: =E14+C15-D15 -> 438.88
E16: =E15+C16-D16 -> 438.88
E17: =E16+C17-D17 -> 438.88
E18: =E17+C18-D18 -> 438.88
E19: =E18+C19-D19 -> 438.88
... E161: =E160+C161-D161 -> 438.88

Sheet SWIFT BRIDGE WIO AED
A1: SWIFT BRIDGE WIO AED
A4: 23.04.2026 | B4: FUND RECD FROM INFINITY SIB AED | C4: 37013 | E4: =C4 -> 37013 | G4: A/C OPENED
A5: 23.04.2026 | B5: TT TRF TO SHRIJI INT EIB AED | D5: 36460 | E5: =E4+C5-D5 -> 553
A6: 24.04.2026 | B6: FUND RECD FROM INFINITY SIB AED | C6: 237474 | E6: =E5+C6-D6 -> 238027
A7: 24.04.2026 | B7: TT TRF TO SHRIJI INT EIB AED | D7: 237465 | E7: =E6+C7-D7 -> 562
E8: =E7+C8-D8 -> 562
E9: =E8+C9-D9 -> 562
E10: =E9+C10-D10 -> 562
E11: =E10+C11-D11 -> 562
E12: =E11+C12-D12 -> 562
E13: =E12+C13-D13 -> 562
E14: =E13+C14-D14 -> 562
E15: =E14+C15-D15 -> 562
E16: =E15+C16-D16 -> 562
E17: =E16+C17-D17 -> 562
E18: =E17+C18-D18 -> 562
E19: =E18+C19-D19 -> 562
... E136: =E135+C136-D136 -> 562

Sheet ORBIT PLUS WIO USD
A1: ORBIT PLUS WIO
E3: =C3 -> 0
A4: 10.02.2026 | B4: FUND RECD FROM GLOBAL ISLAND LTD | C4: 145130 | E4: =E3+C4-D4 -> 145130
A5: 10.02.2026 | B5: USD TO AED | D5: 145120 | E5: =E4+C5-D5 -> 10
A6: 21.02.2026 | B6: FUND RECD FROM GLOBAL ISLAND LTD | C6: 88653.96 | E6: =E5+C6-D6 -> 88663.96
A7: 21.02.2026 | B7: USD TO AED | D7: 88660 | E7: =E6+C7-D7 -> 3.96
A8: 24.02.2026 | B8: FUND RECD FROM GLOBAL ISLAND LTD | C8: 84560.4 | E8: =E7+C8-D8 -> 84564.36
A9: 24.02.2026 | B9: FUND RECD FROM GLOBAL ISLAND LTD | C9: 54900 | E9: =E8+C9-D9 -> 139464.36
A10: 24.02.2026 | B10: FUND RECD FROM COMIDA GOODS WHOLESALERS LLC | C10: 99560.16 | E10: =E9+C10-D10 -> 239024.52
A11: 24.02.2026 | B11: USD TO AED | D11: 239020 | E11: =E10+C11-D11 -> 4.52
A12: 27.02.2026 | B12: FUND RECD FROM GLOBAL ISLAND LTD | C12: 155210 | E12: =E11+C12-D12 -> 155214.52
A13: 27.02.2026 | B13: USD TO AED | D13: 155210 | E13: =E12+C13-D13 -> 4.52
A14: 28.02.2026 | B14: FUND RECD FROM GLOBAL ISLAND LTD | C14: 88200 | E14: =E13+C14-D14 -> 88204.52
A15: 28.02.2026 | B15: USD TO AED | D15: 88200 | E15: =E14+C15-D15 -> 4.52
A16: 04.03.2026 | B16: FUND RECD FROM GLOBAL ISLAND LTD | C16: 174600 | E16: =E15+C16-D16 -> 174604.52
A17: 04.03.2026 | B17: USD TO AED | D17: 174600 | E17: =E16+C17-D17 -> 4.52
A18: 05.03.2026 | B18: FUND RECD FROM GLOBAL ISLAND LTD | C18: 147500 | E18: =E17+C18-D18 -> 147504.52
A19: 05.03.2026 | B19: FUND RECD FROM GLOBAL ISLAND LTD | C19: 194300 | E19: =E18+C19-D19 -> 341804.52
A20: 05.03.2026 | B20: USD TO AED | D20: 341800 | E20: =E19+C20-D20 -> 4.52
A21: 10.03.2026 | B21: FUND RECD FROM GLOBAL ISLAND LTD | C21: 315700 | E21: =E20+C21-D21 -> 315704.52
A22: 10.03.2026 | B22: USD TO AED | D22: 315703 | E22: =E21+C22-D22 -> 1.52
A23: 11.03.2026 | B23: FUND RECD FROM COMIDA GOODS WHOLESALERS LLC | C23: 328900 | E23: =E22+C23-D23 -> 328901.52
A24: 11.03.2026 | B24: USD TO AED | D24: 328900 | E24: =E23+C24-D24 -> 1.52
A25: 12.03.2026 | B25: FUND RECD FROM NIYAT GOODS WHOLESALERS PAYONEER | C25: 374100 | E25: =E24+C25-D25 -> 374101.52
A26: 12.03.2026 | B26: USD TO AED | D26: 374100 | E26: =E25+C26-D26 -> 1.52
A27: 13.03.2026 | B27: FUND RECD FROM ROYAL EN EM PAYONEER | C27: 235700 | E27: =E26+C27-D27 -> 235701.52
A28: 13.03.2026 | B28: FUND RECD FROM GLOBAL ISLAND LTD | C28: 141810 | E28: =E27+C28-D28 -> 377511.52
A29: 13.03.2026 | B29: FUND RECD FROM NIYAT GOODS WHOLESALERS PAYONEER | C29: 153010 | E29: =E28+C29-D29 -> 530521.52
A30: 13.03.2026 | B30: FUND RECD FROM GLOBAL ISLAND LTD | C30: 29860 | E30: =E29+C30-D30 -> 560381.52
A31: 13.03.2026 | B31: USD TO AED | D31: 300000 | E31: =E30+C31-D31 -> 260381.52
A32: 14.03.2026 | B32: USD TO AED | D32: 260380 | E32: =E31+C32-D32 -> 1.52
A33: 17.03.2026 | B33: FUND RECD FROM ROYAL EN EM PAYONEER | C33: 89600 | E33: =E32+C33-D33 -> 89601.52
A34: 17.03.2026 | B34: USD TO AED | D34: 89600 | E34: =E33+C34-D34 -> 1.52
A35: 18.03.2026 | B35: FUND RECD FROM GLOBAL ISLAND LTD | C35: 113010 | E35: =E34+C35-D35 -> 113011.52
A36: 18.03.2026 | B36: USD TO AED | D36: 113010 | E36: =E35+C36-D36 -> 1.52
A37: 23.03.2026 | B37: FUND RECD FROM ROYAL EN EM PAYONEER | C37: 352110 | E37: =E36+C37-D37 -> 352111.52
A38: 23.03.2026 | B38: USD TO AED | D38: 352110 | E38: =E37+C38-D38 -> 1.52
A39: 24.03.2026 | B39: FUND RECD FROM GLOBAL ISLAND LTD | C39: 74510 | E39: =E38+C39-D39 -> 74511.52
A40: 24.03.2026 | B40: USD TO AED | D40: 74510 | E40: =E39+C40-D40 -> 1.52
A41: 03.04.2026 | B41: FUND RECD FROM BOLDWAY AIRWALLEX | C41: 99745 | E41: =E40+C41-D41 -> 99746.52
...

Sheet ORBIT PLUS WIO AED
A1: ORBIT PLUS WIO
E3: =C3 -> 0
C4: 249805 | E4: =E3+C4-D4 -> 249805
D5: 249201 | E5: =E4+C5-D5 -> 604
A6: 05.02.2026 | B6: FUND RECD FROM PINNACLE INT SIB | C6: 207403 | E6: =E5+C6-D6 -> 208007
A7: 05.02.2026 | B7: FUND RECD FROM PINNACLE INT FAB | C7: 142580 | E7: =E6+C7-D7 -> 350587
A8: 05.02.2026 | B8: TT TRF TO FABREX ENTERPRISES BOB (USD 94950) | D8: =348696.26+52.5 -> 348748.76 | E8: =E7+C8-D8 -> 1838.24
A9: 05.02.2026 | B9: CASH DEPOSIT | C9: 10000 | E9: =E8+C9-D9 -> 11838.24
A10: 05.02.2026 | B10: TT TRF TO SILVER STONE WIO AED | D10: 10235 | E10: =E9+C10-D10 -> 1603.24
A11: 10.02.2026 | B11: USD TO AED | C11: 532590.4 | E11: =E10+C11-D11 -> 534193.64
A12: 10.02.2026 | B12: TT TRF TO AMINEX SIB AED | D12: 481013 | E12: =E11+C12-D12 -> 53180.64
A13: 10.02.2026 | B13: CASH DEPOSIT | C13: =94500+104000+2000 -> 200500 | E13: =E12+C13-D13 -> 253680.64
A14: 10.02.2026 | B14: TT TRF TO SILVER STONE WIO AED | D14: 252964 | E14: =E13+C14-D14 -> 716.64
A15: 12.02.2026 | B15: CASH DEPOSIT | C15: 250000 | E15: =E14+C15-D15 -> 250716.64
A16: 12.02.2026 | B16: TT TRF TO SILVER STONE WIO AED | D16: 250145 | E16: =E15+C16-D16 -> 571.64
A17: 13.02.2026 | B17: CASH DEPOSIT | C17: =98500+51000+67500+68000+13500 -> 298500 | E17: =E16+C17-D17 -> 299071.64
A18: 13.02.2026 | B18: FUND RECD FROM AMINEX SIB | C18: 1800 | E18: =E17+C18-D18 -> 300871.64
A19: 13.02.2026 | B19: TT TRF TO MAADAN ALHAZAZ SAR 305807 | D19: =299944.67+52.5 -> 299997.17 | E19: =E18+C19-D19 -> 874.47
A20: 14.02.2026 | B20: FUND RECD FROM PINNACLE INT SIB | C20: 350487 | E20: =E19+C20-D20 -> 351361.47
A21: 14.02.2026 | B21: TT TRF TO MAADAN ALHAZAZ (SAR 356815) | D21: 350035.99 | E21: =E20+C21-D21 -> 1325.48
A22: 17.02.2026 | B22: FUND RECD FROM INFINITY SIB AED | C22: 94211 | E22: =E21+C22-D22 -> 95536.48
A23: 18.02.2026 | B23: FUND RECD FROM ORBIT UBL AED | C23: 274000 | E23: =E22+C23-D23 -> 369536.48
A24: 18.02.2026 | B24: TT TRF TO ALHIJAZ METAL TRADING CO (SAR 374872) | D24: =367697.44+52.5 -> 367749.94 | E24: =E23+C24-D24 -> 1786.54
A25: 20.02.2026 | B25: CASH DEPOSIT | C25: 200000 | E25: =E24+C25-D25 -> 201786.54
A26: 20.02.2026 | B26: FUND RECD FROM PINNACLE GR NBF | C26: 50000 | E26: =E25+C26-D26 -> 251786.54
A27: 20.02.2026 | B27: FUND RECD FROM PINNACLE GR NBF | C27: 50000 | E27: =E26+C27-D27 -> 301786.54
A28: 20.02.2026 | B28: FUND RECD FROM PINNACLE GR NBF | C28: 41012 | E28: =E27+C28-D28 -> 342798.54
A29: 20.02.2026 | B29: FUND RECD FROM PINNACLE INT FAB | C29: 123856 | E29: =E28+C29-D29 -> 466654.54
A30: 20.02.2026 | B30: CASH DEPOSIT | C30: 15000 | E30: =E29+C30-D30 -> 481654.54
A31: 20.02.2026 | B31: TT TRF TO ALHIJAZ METAL TRADING CO (SAR 489242) | D31: =479796.57+52.5 -> 479849.07 | E31: =E30+C31-D31 -> 1805.47
A32: 21.02.2026 | B32: BANK CHARGES | D32: 99 | E32: =E31+C32-D32 -> 1706.47
A33: 21.02.2026 | B33: USD TO AED | C33: 325382.2 | E33: =E32+C33-D33 -> 327088.67
A34: 21.02.2026 | B34: TT TRF TO ALHIJAZ METAL TRADING CO (SAR 244385) | D34: =239640.83+52.5 -> 239693.33 | E34: =E33+C34-D34 -> 87395.34
A35: 21.02.2026 | B35: TT TRF TO AMINEX SIB AED | D35: 86204 | E35: =E34+C35-D35 -> 1191.34
A36: 23.02.2026 | B36: FUND RECD FROM INFINITY SIB AED | C36: 479231 | E36: =E35+C36-D36 -> 480422.34
A37: 23.02.2026 | B37: TT TRF TO ALHIJAZ METAL TRADING CO (SAR 488886) | D37: =479447.41+52.5 -> 479499.91 | E37: =E36+C37-D37 -> 922.43
A38: 24.02.2026 | B38: USD TO AED | C38: 877203.4 | E38: =E37+C38-D38 -> 878125.83
A39: 24.02.2026 | B39: TT TRF TO AMINEX SIB AED | D39: 450213 | E39: =E38+C39-D39 -> 427912.83
A40: 24.02.2026 | B40: TT TRF TO SILVER STONE WIO AED | D40: 426801 | E40: =E39+C40-D40 -> 1111.83
E41: =E40+C41-D41 -> 1111.83
...

Sheet ORBIT PLUS UBL AED
A1: ORBIT PLUS UBL AED
E3: =C3 -> 0
A4: 06.02.2026 | B4: CASH DEPOSIT | C4: 600000 | E4: =E3+C4-D4 -> 600000
A5: 07.02.2026 | B5: TT TRF TO SHRIJI INT EIB AED | D5: 380640 | E5: =E4+C5-D5 -> 219360
A6: 07.02.2026 | B6: BANK CHARGES | D6: 1.05 | E6: =E5+C6-D6 -> 219358.95
A7: 07.02.2026 | B7: TT TRF TO SHRIJI INT EIB AED | D7: 214203 | E7: =E6+C7-D7 -> 5155.95
A8: 07.02.2026 | B8: BANK CHARGES | D8: 1.05 | E8: =E7+C8-D8 -> 5154.9
A9: 07.02.2026 | B9: CASH DEPOSIT | C9: 600000 | E9: =E8+C9-D9 -> 605154.9
A10: 07.02.2026 | B10: TT TRF TO SILVER STONE WIO | D10: 502385 | E10: =E9+C10-D10 -> 102769.9
A11: 07.02.2026 | B11: BANK CHARGES | D11: 1.05 | E11: =E10+C11-D11 -> 102768.85
A12: 09.02.2026 | B12: TT TRF TO AMINEX SIB AED | D12: 97520 | E12: =E11+C12-D12 -> 5248.85
A13: 09.02.2026 | B13: BANK CHARGES | D13: 1.05 | E13: =E12+C13-D13 -> 5247.8
A14: 09.02.2026 | B14: CASH DEPOSIT | C14: 850000 | E14: =E13+C14-D14 -> 855247.8
A15: 09.02.2026 | B15: TT TRF TO AMINEX SIB AED | D15: 452081 | E15: =E14+C15-D15 -> 403166.8
A16: 09.02.2026 | B16: BANK CHARGES | D16: 1.05 | E16: =E15+C16-D16 -> 403165.75
A17: 10.02.2026 | B17: TT TRF TO SILVER STONE WIO | D17: 399856 | E17: =E16+C17-D17 -> 3309.75
A18: 10.02.2026 | B18: BANK CHARGES | D18: 1.05 | E18: =E17+C18-D18 -> 3308.7
A19: 10.02.2026 | B19: CASH DEPOSIT | C19: 1600000 | E19: =E18+C19-D19 -> 1603308.7
A20: 10.02.2026 | B20: TT TRF TO SILVER STONE WIO | D20: 650130 | E20: =E19+C20-D20 -> 953178.7
A21: 12.02.2026 | B21: TT TRF TO M J S STAR EIB AED | D21: 949856 | E21: =E20+C21-D21 -> 3322.7
A22: 12.02.2026 | B22: BANK CHARGES | D22: 1.05 | E22: =E21+C22-D22 -> 3321.65
A23: 12.02.2026 | B23: CASH DEPOSIT | C23: 2400000 | E23: =E22+C23-D23 -> 2403321.6
A24: 12.02.2026 | B24: TT TRF TO M J S STAR EIB AED | D24: 1063000 | E24: =E23+C24-D24 -> 1340321.6
A25: 12.02.2026 | B25: BANK CHARGES | D25: 1.05 | E25: =E24+C25-D25 -> 1340320.6
A26: 12.02.2026 | B26: BANK CHARGES | D26: 1.05 | E26: =E25+C26-D26 -> 1340319.5
A27: 12.02.2026 | B27: TT TRF TO AMINEX SIB AED | D27: 480146 | E27: =E26+C27-D27 -> 860173.55
A28: 12.02.2026 | B28: BANK CHARGES | D28: 1.05 | E28: =E27+C28-D28 -> 860172.5
A29: 12.02.2026 | B29: TT TRF TO ENFLOW SIB AED | D29: 799857 | E29: =E28+C29-D29 -> 60315.5
A30: 12.02.2026 | B30: BANK CHARGES | D30: 1.05 | E30: =E29+C30-D30 -> 60314.45
A31: 17.02.2026 | B31: CASH DEPOSIT | C31: 2500000 | E31: =E30+C31-D31 -> 2560314.4
A32: 17.02.2026 | B32: TT TRF TO AMINEX SIB AED | D32: 612870 | E32: =E31+C32-D32 -> 1947444.4
A33: 17.02.2026 | B33: BANK CHARGES | D33: 1.05 | E33: =E32+C33-D33 -> 1947443.4
A34: 17.02.2026 | B34: TT TRF TO AMINEX SIB AED | D34: 637133 | E34: =E33+C34-D34 -> 1310310.4
A35: 17.02.2026 | B35: BANK CHARGES | D35: 1.05 | E35: =E34+C35-D35 -> 1310309.3
A36: 17.02.2026 | B36: TT TRF TO AMINEX SIB AED | D36: 145213 | E36: =E35+C36-D36 -> 1165096.3
A37: 17.02.2026 | B37: BANK CHARGES | D37: 1.05 | E37: =E36+C37-D37 -> 1165095.3
A38: 18.02.2026 | B38: TT TRF TO ORBIT PLUS WIO | D38: 274000 | E38: =E37+C38-D38 -> 891095.3
A39: 18.02.2026 | B39: BANK CHARGES | D39: 1.05 | E39: =E38+C39-D39 -> 891094.25
A40: 18.02.2026 | B40: TT TRF TO SHRIJI INT EIB AED | D40: 879080 | E40: =E39+C40-D40 -> 12014.25
A41: 18.02.2026 | B41: BANK CHARGES | D41: 1.05 | E41: =E40+C41-D41 -> 12013.2
...

Sheet ORBIT PLUS SIB
C3: 5000 | E3: =C3 -> 5000
B4: BANK CHARGES | D4: 628.5 | E4: =E3+C4-D4 -> 4371.5
A5: 12.12.2025 | B5: CASH DEPOSIT | C5: 244000 | E5: =E4+C5-D5 -> 248371.5
A6: 12.12.2025 | B6: TT TRF TO AMINEX SIB | D6: 246908 | E6: =E5+C6-D6 -> 1463.5
A7: 12.12.2025 | B7: BANK CHARGES | D7: 425.25 | E7: =E6+C7-D7 -> 1038.25
A8: 16.12.2025 | B8: CASH DEPOSIT | C8: 250000 | E8: =E7+C8-D8 -> 251038.25
A9: 16.12.2025 | B9: TT TRF TO SHRIJI INT EIB | D9: 250031 | E9: =E8+C9-D9 -> 1007.25
A10: 16.12.2025 | B10: BANK CHARGES | D10: 1.05 | E10: =E9+C10-D10 -> 1006.2
A11: 16.12.2025 | B11: CASH DEPOSIT | C11: 100000 | E11: =E10+C11-D11 -> 101006.2
A12: 16.12.2025 | B12: TT TRF TO AMINEX SIB | D12: 100264 | E12: =E11+C12-D12 -> 742.2
A13: 17.12.2025 | B13: CASH DEPOSIT | C13: 250000 | E13: =E12+C13-D13 -> 250742.2
A14: 17.12.2025 | B14: CASH DEPOSIT | C14: 99500 | E14: =E13+C14-D14 -> 350242.2
A15: 17.12.2025 | B15: TT TRF TO ROYAL ENBD AED | D15: 349985 | E15: =E14+C15-D15 -> 257.2
A16: 17.12.2025 | B16: BANK CHARGES | D16: 1.05 | E16: =E15+C16-D16 -> 256.15
A17: 19.12.2025 | B17: CASH DEPOSIT | C17: 250000 | E17: =E16+C17-D17 -> 250256.15
A18: 19.12.2025 | B18: TT TRF TO AMINEX SIB | D18: 249893 | E18: =E17+C18-D18 -> 363.15
A19: 31.12.2025 | B19: CASH DEPOSIT | C19: 100000 | E19: =E18+C19-D19 -> 100363.15
A20: 31.12.2025 | B20: FUND RECD FROM BULLFROG NBF | C20: 154000 | E20: =E19+C20-D20 -> 254363.15
A21: 31.12.2025 | B21: FUND RECD FROM BULLFROG NBF | C21: 177023 | E21: =E20+C21-D21 -> 431386.15
A22: 31.12.2025 | B22: TT TRF TO JUDICIARY DEPT. ABU DHABI COURT AJIT RAO | D22: 400000 | E22: =E21+C22-D22 -> 31386.15
A23: 31.12.2025 | B23: TT TRF TO ROYAL SIB AED | D23: 31023 | E23: =E22+C23-D23 -> 363.15
A24: 02.01.2026 | B24: BANK CHARGES | D24: 336 | E24: =E23+C24-D24 -> 27.15
A25: 02.01.2026 | B25: BANK CHARGES | D25: 20 | E25: =E24+C25-D25 -> 7.15
A26: 02.01.2026 | B26: BANK CHARGES | D26: 71.05 | E26: =E25+C26-D26 -> -63.9
A27: 16.01.2026 | B27: CASH DEPOSIT | C27: 142500 | E27: =E26+C27-D27 -> 142436.1
A28: 16.01.2026 | B28: TT TRF TO AMINEX SIB | D28: 142031 | E28: =E27+C28-D28 -> 405.1
A29: 19.01.2026 | B29: CASH DEPOSIT | C29: 79900 | E29: =E28+C29-D29 -> 80305.1
A30: 19.01.2026 | B30: TT TRF TO AMINEX SIB | D30: 79803 | E30: =E29+C30-D30 -> 502.1
A31: 20.01.2026 | B31: CASH DEPOSIT | C31: 263000 | E31: =E30+C31-D31 -> 263502.1
A32: 20.01.2026 | B32: TT TRF TO ROYAL ENBD AED | D32: 263003 | E32: =E31+C32-D32 -> 499.1
A33: 20.01.2026 | B33: BANK CHARGES | D33: 1.05 | E33: =E32+C33-D33 -> 498.05
A34: 21.01.2026 | B34: CASH DEPOSIT | C34: 250000 | E34: =E33+C34-D34 -> 250498.05
A35: 21.01.2026 | B35: TT TRF TO SILVER STONE WIO | D35: 250031 | E35: =E34+C35-D35 -> 467.05
A36: 21.01.2026 | B36: BANK CHARGES | D36: 1.05 | E36: =E35+C36-D36 -> 466
A37: 23.01.2026 | B37: CASH DEPOSIT | C37: 200000 | E37: =E36+C37-D37 -> 200466
A38: 23.01.2026 | B38: TT TRF TO SILVER STONE WIO | D38: 200104 | E38: =E37+C38-D38 -> 362
A39: 23.01.2026 | B39: BANK CHARGES | D39: 1.05 | E39: =E38+C39-D39 -> 360.95
A40: 27.01.2026 | B40: CASH DEPOSIT | C40: 200000 | E40: =E39+C40-D40 -> 200360.95
A41: 27.01.2026 | B41: TT TRF TO AMINEX SIB | D41: 200013 | E41: =E40+C41-D41 -> 347.95
A42: 28.01.2026 | B42: CASH DEPOSIT | C42: 250000 | E42: =E41+C42-D42 -> 250347.95
...

Sheet ORBIT PLUS ADIB AED
A1: ORBIT PLUS ADIB AED
E3: =C3 -> 0
A4: 26.02.2026 | B4: FUND RECD FROM PINNACLE GR NBF | C4: 6000 | E4: =E3+C4-D4 -> 6000
A5: 27.02.2026 | B5: BANK CHARGES | D5: 105 | E5: =E4+C5-D5 -> 5895
A6: 27.02.2026 | B6: AED TO USD | D6: 927.38 | E6: =E5+C6-D6 -> 4967.62
A7: 28.02.2026 | B7: AED TO USD | D7: 4700 | E7: =E6+C7-D7 -> 267.62
A8: 01.03.2026 | B8: BANK CHARGES | D8: 105 | E8: =E7+C8-D8 -> 162.62
A9: 02.05.2026 | B9: BANK CHARGES | D9: 105 | E9: =E8+C9-D9 -> 57.62
E10: =E9+C10-D10 -> 57.62
E11: =E10+C11-D11 -> 57.62
E12: =E11+C12-D12 -> 57.62
E13: =E12+C13-D13 -> 57.62
E14: =E13+C14-D14 -> 57.62
E15: =E14+C15-D15 -> 57.62
E16: =E15+C16-D16 -> 57.62
E17: =E16+C17-D17 -> 57.62
E18: =E17+C18-D18 -> 57.62
E19: =E18+C19-D19 -> 57.62
E20: =E19+C20-D20 -> 57.62
E21: =E20+C21-D21 -> 57.62
... E140: =E139+C140-D140 -> 57.62

Sheet ORBIT PLUS ADIB USD
A1: ORBIT PLUS ADIB USD
E3: =C3 -> 0
A4: 27.02.2026 | B4: AED TO USD | C4: 250 | E4: =E3+C4-D4 -> 250
A5: 28.02.2026 | B5: AED TO USD | C5: 1267.02 | E5: =E4+C5-D5 -> 1517.02
A6: 01.04.2026 | B6: BANK INTEREST | C6: 0.36 | E6: =E5+C6-D6 -> 1517.38
E7: =E6+C7-D7 -> 1517.38
E8: =E7+C8-D8 -> 1517.38
E9: =E8+C9-D9 -> 1517.38
E10: =E9+C10-D10 -> 1517.38
E11: =E10+C11-D11 -> 1517.38
E12: =E11+C12-D12 -> 1517.38
E13: =E12+C13-D13 -> 1517.38
E14: =E13+C14-D14 -> 1517.38
E15: =E14+C15-D15 -> 1517.38
E16: =E15+C16-D16 -> 1517.38
E17: =E16+C17-D17 -> 1517.38
E18: =E17+C18-D18 -> 1517.38
... E100: =E99+C100-D100 -> 1517.38

Sheet CROSSFIT MSQ
A1: CROSSFIT MSQ AED
A2: DATE | B2: PARTICULARS | C2: DEPOSIT | D2: WITHDRAWAL | E2: BALANCE
C3: 11021 | E3: =C3 -> 11021
D4: 9500 | E4: =E3+C4-D4 -> 1521
A5: 19.11.2025 | B5: CASH DEPSOT | C5: 299000 | E5: =E4+C5-D5 -> 300521
A6: 19.11.2025 | B6: TT TRF TO AMINEX ADIB | D6: 100000 | E6: =E5+C6-D6 -> 200521
A7: 19.11.2025 | B7: TT TRF TO AMINEX ADIB | D7: 199696 | E7: =E6+C7-D7 -> 825
A8: 19.11.2025 | B8: BANK CHARGES | D8: 2.1 | E8: =E7+C8-D8 -> 822.9
A9: 13.12.2025 | B9: FUND RECD FROM SILVER CROSS EQUIPMENT MISR | C9: 980528 | E9: =E8+C9-D9 -> 981350.9
A10: 13.12.2025 | B10: TT TRF TO SILVER SAGE MSQ | D10: 120018 | E10: =E9+C10-D10 -> 861332.9
A11: 23.12.2025 | B11: CASH DEPOSIT | C11: 120500 | E11: =E10+C11-D11 -> 981832.9
A12: 23.12.2025 | B12: BANK CHARGES | D12: 525 | E12: =E11+C12-D12 -> 981307.9
A13: 25.12.2025 | B13: RETURNED RECD FROM SILVER CROSS EQUIPMENT MISR | D13: 980528 | E13: =E12+C13-D13 -> 779.9 | F13: =+E13-779.9 -> 2.3305802e-11
A14: 02.01.2026 | B14: BANK CHARGES | D14: 210 | E14: =E13+C14-D14 -> 569.9
E15: =E14+C15-D15 -> 569.9
E16: =E15+C16-D16 -> 569.9
E17: =E16+C17-D17 -> 569.9
E18: =E17+C18-D18 -> 569.9
E19: =E18+C19-D19 -> 569.9
E20: =E19+C20-D20 -> 569.9
E21: =E20+C21-D21 -> 569.9
E22: =E21+C22-D22 -> 569.9
E23: =E22+C23-D23 -> 569.9
E24: =E23+C24-D24 -> 569.9
E25: =E24+C25-D25 -> 569.9
E26: =E25+C26-D26 -> 569.9
... E100: =E99+C100-D100 -> 569.9

Sheet CROSSFIT SIB AED
A1: CROSSFIT SIB AED
A2: DATE | B2: PARTICULARS | C2: DEPOSIT | D2: WITHDRAWAL | E2: BALANCE
A3: 30.01.2026 | C3: 5000 | E3: =C3 -> 5000
A4: 02.02.2026 | B4: BANK CHARGES | D4: 210 | E4: =E3+C4-D4 -> 4790
A5: 06.03.2026 | B5: BANK CHARGES | D5: 425.25 | E5: =E4+C5-D5 -> 4364.75
A6: 01.04.2026 | B6: BANK CHARGES | D6: 425.25 | E6: =E5+C6-D6 -> 3939.5
A7: 07.04.2026 | B7: TT TRF TO AGNIRA INT WIO AED | D7: 1000 | E7: =E6+C7-D7 -> 2939.5
A8: 07.04.2026 | B8: BANK CHARGES | D8: 0.5 | E8: =E7+C8-D8 -> 2939
A9: 07.04.2026 | B9: FUND RECD FROM OPTICORE SIB AED | C9: 202860 | E9: =E8+C9-D9 -> 205799
A10: 07.04.2026 | B10: TT TRF TO AGNIRA INT WIO AED | D10: 204890 | E10: =E9+C10-D10 -> 909
A11: 07.04.2026 | B11: BANK CHARGES | D11: 1.05 | E11: =E10+C11-D11 -> 907.95
A12: 10.04.2026 | B12: CASH DEPOSIT | E12: =E11+C12-D12 -> 907.95
A13: 10.04.2026 | B13: FUND RECD FROM OPTICORE SIB AED | C13: 250100 | E13: =E12+C13-D13 -> 251007.95
A14: 10.04.2026 | B14: CASH DEPOSIT | C14: 200000 | E14: =E13+C14-D14 -> 451007.95
A15: 10.04.2026 | B15: TT TRF TO SWIFT BRIDGE SIB | D15: 450645 | E15: =E14+C15-D15 -> 362.95
A16: 15.04.2026 | B16: CASH DEPOSIT | C16: 100000 | E16: =E15+C16-D16 -> 100362.95
A17: 15.04.2026 | B17: FUND RECD FROM OPTICORE SIB AED | C17: 243900 | E17: =E16+C17-D17 -> 344262.95
A18: 15.04.2026 | B18: TT TRF TO AGINCO MSQ | D18: 110230 | E18: =E17+C18-D18 -> 234032.95
A19: 15.04.2026 | B19: BANK CHARGES | D19: 1.05 | E19: =E18+C19-D19 -> 234031.9
A20: 15.04.2026 | B20: FUND RECD FROM M J S STAR SIB AED | C20: 201560 | E20: =E19+C20-D20 -> 435591.9
A21: 15.04.2026 | B21: TT TRF TO AGINCO MSQ | D21: 434550 | E21: =E20+C21-D21 -> 1041.9
A22: 15.04.2026 | B22: BANK CHARGES | D22: 1.05 | E22: =E21+C22-D22 -> 1040.85
A23: 17.04.2026 | B23: CASH DEPOSIT | C23: 56000 | E23: =E22+C23-D23 -> 57040.85
A24: 17.04.2026 | B24: TT TRF TO AMINEX SIB | D24: 56500 | E24: =E23+C24-D24 -> 540.85
A25: 30.04.2026 | B25: CASH DEPOSIT | C25: 200000 | E25: =E24+C25-D25 -> 200540.85
A26: 30.04.2026 | B26: TT TRF TO SWIFT BRIDGE SIB | D26: 200243 | E26: =E25+C26-D26 -> 297.85
E27: =E26+C27-D27 -> 297.85
E28: =E27+C28-D28 -> 297.85
E29: =E28+C29-D29 -> 297.85
E30: =E29+C30-D30 -> 297.85
E31: =E30+C31-D31 -> 297.85
E32: =E31+C32-D32 -> 297.85
E33: =E32+C33-D33 -> 297.85
E34: =E33+C34-D34 -> 297.85
E35: =E34+C35-D35 -> 297.85
E36: =E35+C36-D36 -> 297.85
E37: =E36+C37-D37 -> 297.85
E38: =E37+C38-D38 -> 297.85
... E130: =E129+C130-D130 -> 297.85

Sheet SWIFT BRIDGE ENBD AED
A1: SWIFT BRIDGE ENBD AED
A4: 14.03.2026 | B4: FUND RECD FROM SWIFT BRIDGE SIB AED | C4: 5000 | E4: =C4 -> 5000
A5: 10.04.2026 | B5: BANK CHARGES | D5: =7.5+150+4.95 -> 162.45 | E5: =E4+C5-D5 -> 4837.55
A6: 10.04.2026 | B6: BANK CHARGES | D6: 99 | E6: =E5+C6-D6 -> 4738.55
E7: =E6+C7-D7 -> 4738.55
E8: =E7+C8-D8 -> 4738.55
E9: =E8+C9-D9 -> 4738.55
E10: =E9+C10-D10 -> 4738.55
E11: =E10+C11-D11 -> 4738.55
E12: =E11+C12-D12 -> 4738.55
E13: =E12+C13-D13 -> 4738.55
E14: =E13+C14-D14 -> 4738.55
E15: =E14+C15-D15 -> 4738.55
E16: =E15+C16-D16 -> 4738.55
E17: =E16+C17-D17 -> 4738.55
E18: =E17+C18-D18 -> 4738.55
... E210: =E209+C210-D210 -> 4738.55

Sheet SWIFT BRIDGE MSQ AED
A1: SWIFT BRIDGE AED
A4: 23.10.2025 | B4: FUND RECD FROM | C4: 12896 | E4: =C4 -> 12896
A5: 23.10.2025 | B5: BANK CHARGES | D5: 640.5 | E5: =E4+C5-D5 -> 12255.5
A6: 24.10.2025 | B6: CHQ PAID 000001 TO BLUE TITAN BUSINESS CENTER | D6: 8333 | E6: =E5+C6-D6 -> 3922.5
B7: BANK CHARGES | D7: 210 | E7: =E6+C7-D7 -> 3712.5
B8: BANK CHARGES | D8: 315 | E8: =E7+C8-D8 -> 3397.5
A9: 01.12.2025 | B9: BANK CHARGES | D9: 210 | E9: =E8+C9-D9 -> 3187.5
A10: 01.12.2025 | B10: BANK CHARGES | D10: 315 | E10: =E9+C10-D10 -> 2872.5
A11: 02.01.2026 | B11: BANK CHARGES | D11: 210 | E11: =E10+C11-D11 -> 2662.5
A12: 24.02.2026 | B12: FUND RECD FROM CAPS LOCK FAB AED | C12: 8623 | E12: =E11+C12-D12 -> 11285.5
A13: 24.02.2026 | B13: BANK CHARGES | D13: 210 | E13: =E12+C13-D13 -> 11075.5
A14: 25.02.2026 | B14: CHQ PAID TO BLUE TITAN BUSINESS CENTER | D14: 8333 | E14: =E13+C14-D14 -> 2742.5
A15: 09.04.2026 | B15: BANK CHARGES | D15: 210 | E15: =E14+C15-D15 -> 2532.5
A16: 09.04.2026 | B16: BANK CHARGES | D16: 210 | E16: =E15+C16-D16 -> 2322.5
A17: 09.04.2026 | B17: FUND RECD FROM BLACK PEPPER NBF | C17: 7231 | E17: =E16+C17-D17 -> 9553.5
A18: 13.04.2026 | B18: CHQ PAID TO ALI SADEK HUSSAIN AL JAFFAR AND FUAD | D18: 8250 | E18: =E17+C18-D18 -> 1303.5
E19: =E18+C19-D19 -> 1303.5
E20: =E19+C20-D20 -> 1303.5
E21: =E20+C21-D21 -> 1303.5
E22: =E21+C22-D22 -> 1303.5
E23: =E22+C23-D23 -> 1303.5
E24: =E23+C24-D24 -> 1303.5
E25: =E24+C25-D25 -> 1303.5
E26: =E25+C26-D26 -> 1303.5
E27: =E26+C27-D27 -> 1303.5
E28: =E27+C28-D28 -> 1303.5
E29: =E28+C29-D29 -> 1303.5
E30: =E29+C30-D30 -> 1303.5
... E210: =E209+C210-D210 -> 1303.5

Sheet TRADERS EIB
A1: TRADERS VENTURES EIB AED
A2: DATE | B2: PARTICULAR | C2: DEPOSIT | D2: WITHDRAWAL | E2: BALANCE
A3: 07.10.2025 | B3: BANK CHARGES | E3: 1225.43
A4: 02.12.2025 | B4: BANK CHARGES | D4: 577.5 | E4: =E3+C4-D4 -> 647.93 | F4: =+E4-647.93 -> 0
A5: 02.01.2026 | B5: BANK CHARGES | D5: 225 | E5: =E4+C5-D5 -> 422.93
A6: 02.01.2026 | B6: BANK CHARGES | D6: 11 | E6: =E5+C6-D6 -> 411.93
A7: 07.02.2026 | B7: FUND RECD FROM ORBIT PLUS SIB AED | C7: 1000 | E7: =E6+C7-D7 -> 1411.93
A8: 07.02.2026 | B8: FUND RECD FROM ORBIT PLUS SIB AED | C8: 49015 | E8: =E7+C8-D8 -> 50426.93
A9: 09.02.2026 | B9: TT TRF TO SWIFT BRIDGE SIB AED | D9: 49047 | E9: =E8+C9-D9 -> 1379.93
A10: 09.02.2026 | B10: BANK CHARGES | D10: 1.05 | E10: =E9+C10-D10 -> 1378.88
A11: 06.03.2026 | B11: BANK CHARGES | D11: 631.3 | E11: =E10+C11-D11 -> 747.58
A12: 10.03.2026 | B12: FUND RECD FROM COMIDA NBF | C12: 9700 | E12: =E11+C12-D12 -> 10447.58
A13: 10.03.2026 | B13: TT TRF TO CRIF GULF CITI AED | D13: 9640.31 | E13: =E12+C13-D13 -> 807.27
A14: 25.03.2026 | B14: FUND RECD FROM AMINEX SIB AED | C14: 99588 | E14: =E13+C14-D14 -> 100395.27
A15: 25.03.2026 | B15: FUND RECD FROM AMINEX SIB AED | C15: 1863 | E15: =E14+C15-D15 -> 102258.27
A16: 25.03.2026 | B16: TT TRF TO DSK LEGAL (USD 27487) | D16: 101482 | E16: =E15+C16-D16 -> 776.27
A17: 11.04.2026 | B17: BANK CHARGES | D17: 290.85 | E17: =E16+C17-D17 -> 485.42
A18: 11.04.2026 | B18: FUND RECD FROM RAYMOND WIO | C18: 100 | E18: =E17+C18-D18 -> 585.42
A19: 11.04.2026 | B19: FUND RECD FROM RAYMOND WIO | C19: 333000 | E19: =E18+C19-D19 -> 333585.42
A20: 15.04.2026 | B20: TT TRF TO SWIFT BRIDGE SIB AED | D20: 332500 | E20: =E19+C20-D20 -> 1085.42
A21: 15.04.2026 | B21: BANK CHARGES | D21: 1.05 | E21: =E20+C21-D21 -> 1084.37
E22: =E21+C22-D22 -> 1084.37
E23: =E22+C23-D23 -> 1084.37
E24: =E23+C24-D24 -> 1084.37
E25: =E24+C25-D25 -> 1084.37
E26: =E25+C26-D26 -> 1084.37
E27: =E26+C27-D27 -> 1084.37
E28: =E27+C28-D28 -> 1084.37
E29: =E28+C29-D29 -> 1084.37
E30: =E29+C30-D30 -> 1084.37
E31: =E30+C31-D31 -> 1084.37
E32: =E31+C32-D32 -> 1084.37
E33: =E32+C33-D33 -> 1084.37
... E100: =E99+C100-D100 -> 1084.37

Sheet GLUCKRICH MISR AED
A1: GLUCKRICH MISR AED
A2: DATE | B2: PARTICULAR | C2: DEPOSIT | D2: WITHDRAWAL | E2: BALANCE
B3: O/P BAL | E3: 17931.15
A4: 04.10.2025 | B4: FUND RECD FROM PINNACLE GR NBF | C4: 100409 | E4: =E3+C4-D4 -> 118340.15
A5: 04.10.2025 | B5: SALARY PAID SANDEEP DHANUKA | D5: 75000 | E5: =E4+C5-D5 -> 43340.15 | J5: =+E6-43329.65 -> 0
A6: 04.10.2025 | B6: BANK CHARGES | D6: 10.5 | E6: =E5+C6-D6 -> 43329.65
A7: 14.10.2025 | B7: FUND RECD FROM PINNACLE GR NBF | C7: 62301 | E7: =E6+C7-D7 -> 105630.65
A8: 15.10.2025 | B8: TT TRF TO ASHISH DHANUKA MSQ AED | D8: 100000 | E8: =E7+C8-D8 -> 5630.65
A9: 15.10.2025 | B9: FUND RECD FROM PINNACLE GR NBF | C9: 21325 | E9: =E8+C9-D9 -> 26955.65
A10: 15.10.2025 | B10: TT TRF TO ASHISH DHANUKA MSQ AED | D10: 15000 | E10: =E9+C10-D10 -> 11955.65
A11: 15.10.2025 | B11: BANK CHARGES | D11: 10.5 | E11: =E10+C11-D11 -> 11945.15
A12: 14.11.2025 | B12: FUND RECD FROM PINNACLE GR NBF | C12: 737286 | E12: =E11+C12-D12 -> 749231.15
A13: 14.11.2025 | B13: FUND RECD FROM PINNACLE GR NBF | C13: 18596 | E13: =E12+C13-D13 -> 767827.15
A14: 17.11.2025 | B14: TT TRF TO SECOND STREET SBM (USD 206000) | D14: =206000*3.68 -> 758080 | E14: =E13+C14-D14 -> 9747.15
A15: 19.11.2025 | B15: BANK CHARGES | D15: 52.5 | E15: =E14+C15-D15 -> 9694.65
A16: 19.11.2025 | C16: 17.11 | E16: =E15+C16-D16 -> 9711.76
A17: 10.12.2025 | B17: TT TRF TO GLUCKRICH NBF AED | D17: 5000 | E17: =E16+C17-D17 -> 4711.76
E18: =E17+C18-D18 -> 4711.76
E19: =E18+C19-D19 -> 4711.76
E20: =E19+C20-D20 -> 4711.76
E21: =E20+C21-D21 -> 4711.76
E22: =E21+C22-D22 -> 4711.76
E23: =E22+C23-D23 -> 4711.76
E24: =E23+C24-D24 -> 4711.76
E25: =E24+C25-D25 -> 4711.76
E26: =E25+C26-D26 -> 4711.76
E27: =E26+C27-D27 -> 4711.76
E28: =E27+C28-D28 -> 4711.76
E29: =E28+C29-D29 -> 4711.76
... E100: =E99+C100-D100 -> 4711.76

Sheet GLUCKRICH NBF AED
A1: GLUCKRICH NBF AED
A2: DATE | B2: PARTICULAR | C2: DEPOSIT | D2: WITHDRAWAL | E2: BALANCE
A3: 10.12.2025 | B3: FUND RECD FROM GLUCKRICH MISR AED | C3: 5000 | E3: 5000
A4: 10.12.2025 | B4: BANK CHARGES | D4: 1.05 | E4: =E3+C4-D4 -> 4998.95
A5: 05.01.2026 | B5: FUND RECD FROM PINNACLE INT | C5: 26235 | E5: =E4+C5-D5 -> 31233.95
A6: 05.01.2026 | B6: FUND RECD FROM PINNACLE INT | C6: 2301 | E6: =E5+C6-D6 -> 33534.95
A7: 05.01.2026 | B7: TT TRF TO ASHISH DHANUKA | D7: 31000 | E7: =E6+C7-D7 -> 2534.95
A8: 06.01.2026 | B8: FUND RECD FROM PINNACLE GR NBF | C8: 3520 | E8: =E7+C8-D8 -> 6054.95
A9: 31.01.2026 | B9: BANK CHARGES | D9: =350+17.5 -> 367.5 | E9: =E8+C9-D9 -> 5687.45
A10: 21.02.2026 | B10: USD TO AED | D10: =368.75+17.5 -> 386.25 | E10: =E9+C10-D10 -> 5301.2
A11: 28.02.2026 | B11: BANK CHARGES | D11: 350 | E11: =E10+C11-D11 -> 4951.2
A12: 30.03.2026 | B12: USD TO AED | C12: 1082.92 | E12: =E11+C12-D12 -> 6034.12
A13: 02.04.2026 | B13: FUND RECD FROM PINNACLE GR NBF | C13: 198563 | E13: =E12+C13-D13 -> 204597.12
A14: 02.04.2026 | B14: BANK CHARGES | D14: 350 | E14: =E13+C14-D14 -> 204247.12
A15: 02.04.2026 | B15: BANK CHARGES | D15: 17.5 | E15: =E14+C15-D15 -> 204229.62
A16: 02.04.2026 | B16: TT TRF TO COMIDA NBF AED | D16: 203150 | E16: =E15+C16-D16 -> 1079.62
A17: 24.04.2026 | B17: FUND RECD FROM PINNACLE GR NBF | C17: 36000 | E17: =E16+C17-D17 -> 37079.62
A18: 24.04.2026 | B18: TT TRF TO ASHISH DHANUKA WIO AED | D18: 36000 | E18: =E17+C18-D18 -> 1079.62
E19: =E18+C19-D19 -> 1079.62
E20: =E19+C20-D20 -> 1079.62
E21: =E20+C21-D21 -> 1079.62
E22: =E21+C22-D22 -> 1079.62
E23: =E22+C23-D23 -> 1079.62
E24: =E23+C24-D24 -> 1079.62
E25: =E24+C25-D25 -> 1079.62
E26: =E25+C26-D26 -> 1079.62
E27: =E26+C27-D27 -> 1079.62
E28: =E27+C28-D28 -> 1079.62
E29: =E28+C29-D29 -> 1079.62
E30: =E29+C30-D30 -> 1079.62
... E100: =E99+C100-D100 -> 1079.62

Sheet GLUCKRICH NBF USD
A1: GLUCKRICH NBF USD
A2: DATE | B2: PARTICULAR | C2: DEPOSIT | D2: WITHDRAWAL | E2: BALANCE
A3: 21.02.2026 | B3: AED TO USD | C3: 100 | E3: 100
A4: 12.03.2026 | B4: FUND RECD FROM PINNACLE GR NBF USD | C4: 100 | E4: =E3+C4-D4 -> 200
A5: 12.03.2026 | B5: FUND RECD FROM PINNACLE GR NBF USD | C5: 200100 | E5: =E4+C5-D5 -> 200300
A6: 12.03.2026 | B6: TT TRF MINERVA SBM | D6: 200012 | E6: =E5+C6-D6 -> 288
A7: 13.03.2026 | B7: FUND RECD FROM PINNACLE GR NBF USD | C7: 99900 | E7: =E6+C7-D7 -> 100188
A8: 13.03.2026 | B8: TT TRF MINERVA SBM | D8: =100003+9.53+0.48 -> 100013.01 | E8: =E7+C8-D8 -> 174.99
A9: 14.03.2026 | B9: FUND RECD FROM SECOND STREET PARTNERS | C9: 99991 | E9: =E8+C9-D9 -> 100165.99
A10: 14.03.2026 | B10: BANK CHARGES | D10: 5.45 | E10: =E9+C10-D10 -> 100160.54
A11: 14.03.2026 | B11: BANK CHARGES | D11: 0.27 | E11: =E10+C11-D11 -> 100160.27
A12: 14.03.2026 | B12: BANK CHARGES | D12: 9.53 | E12: =E11+C12-D12 -> 100150.74
A13: 14.03.2026 | B13: BANK CHARGES | D13: 0.48 | E13: =E12+C13-D13 -> 100150.26
A14: 16.03.2026 | B14: FUND RECD FROM PINNACLE GR NBF USD | C14: 73000 | E14: =E13+C14-D14 -> 173150.26
A15: 16.03.2026 | B15: FUND RECD FROM PINNACLE GR NBF USD | C15: 27183.67 | E15: =E14+C15-D15 -> 200333.93
A16: 16.03.2026 | B16: TT TRF MINERVA SBM | D16: 200011 | E16: =E15+C16-D16 -> 322.93
A17: 16.03.2026 | B17: BANK CHARGES | D17: 10.01 | E17: =E16+C17-D17 -> 312.92
A18: 30.03.2026 | B18: BANK CHARGES | D18: 15 | E18: =E17+C18-D18 -> 297.92
A19: 30.03.2026 | B19: USD TO AED | D19: 296 | E19: =E18+C19-D19 -> 1.92
E20: =E19+C20-D20 -> 1.92
E21: =E20+C21-D21 -> 1.92
E22: =E21+C22-D22 -> 1.92
E23: =E22+C23-D23 -> 1.92
E24: =E23+C24-D24 -> 1.92
E25: =E24+C25-D25 -> 1.92
E26: =E25+C26-D26 -> 1.92
E27: =E26+C27-D27 -> 1.92
E28: =E27+C28-D28 -> 1.92
E29: =E28+C29-D29 -> 1.92
E30: =E29+C30-D30 -> 1.92
E31: =E30+C31-D31 -> 1.92
... E100: =E99+C100-D100 -> 1.92

Sheet GOLDENOVA RAK AED
A1: GOLDENOVA RAK AED
A3: DATE | B3: PARTICULAR | C3: DEPOSIT | D3: WITHDRAWAL | E3: BALANCE
A5: 02.10.2025 | B5: FUND RECD | C5: 10 | E5: =E4+C5-D5 -> 10
A6: 02.10.2025 | B6: FUND RECD FROM BLACK PEPPER GT NBF | C6: 5210 | E6: =E5+C6-D6 -> 5220
A7: 02.10.2025 | B7: BANK CHARGES | D7: 52.5 | E7: =E6+C7-D7 -> 5167.5
A8: 06.10.2025 | B8: BANK CHARGES | D8: 51.45 | E8: =E7+C8-D8 -> 5116.05
A9: 31.10.2025 | B9: BANK CHARGES | D9: 155.4 | E9: =E8+C9-D9 -> 4960.65 | F9: =+E9-4960.65 -> 0
A10: 23.12.2025 | B10: TT TRF TO RED STONE WIO | D10: 4500 | E10: =E9+C10-D10 -> 460.65
A11: 23.12.2025 | B11: BANK CHARGES | D11: 4.2 | E11: =E10+C11-D11 -> 456.45
A12: 02.01.2026 | B12: BANK CHARGES | D12: 51.45 | E12: =E11+C12-D12 -> 405
A13: 02.01.2026 | B13: BANK CHARGES | D13: 103.95 | E13: =E12+C13-D13 -> 301.05
A14: 01.04.2026 | B14: BANK CHARGES | D14: 301.05 | E14: =E13+C14-D14 -> 5.6843419e-13
E15: =E14+C15-D15 -> 5.6843419e-13
E16: =E15+C16-D16 -> 5.6843419e-13
E17: =E16+C17-D17 -> 5.6843419e-13
E18: =E17+C18-D18 -> 5.6843419e-13
E19: =E18+C19-D19 -> 5.6843419e-13
E20: =E19+C20-D20 -> 5.6843419e-13
E21: =E20+C21-D21 -> 5.6843419e-13
E22: =E21+C22-D22 -> 5.6843419e-13
E23: =E22+C23-D23 -> 5.6843419e-13
E24: =E23+C24-D24 -> 5.6843419e-13
E25: =E24+C25-D25 -> 5.6843419e-13
E26: =E25+C26-D26 -> 5.6843419e-13
... E118: =E117+C118-D118 -> 5.6843419e-13

Sheet IDEA GROVE EIB AED
A1: IDEA GROVE EIB AED
A3: DATE | B3: PARTICULAR | C3: DEPOSIT | D3: WITHDRAWAL | E3: BALANCE
B4: PARTICULAR
A5: 09.08.2025 | B5: FUND RECD FROM IDEA GROVE | C5: 1500 | E5: =E4+C5-D5 -> 1500
A6: 10.08.2025 | B6: BANK CHARGES | D6: =225+11.25+225+11.25+52.5 -> 525 | E6: =E5+C6-D6 -> 975
A7: 29-08-2025 | B7: FUND RECD FROM PINNACLE INT AED | C7: 9852 | E7: =E6+C7-D7 -> 10827
A8: 02.09.2025 | B8: BANK CHARGES | D8: =225+11.25 -> 236.25 | E8: =E7+C8-D8 -> 10590.75
A9: 02.09.2025 | B9: BANK CHARGES | D9: 52.5 | E9: =E8+C9-D9 -> 10538.25
A10: 02.09.2025 | B10: FUND RECD FROM PINNACLE INT AED | C10: 56379 | E10: =E9+C10-D10 -> 66917.25
A11: 02.09.2025 | B11: TT TRF TO ROYAL ENBD | D11: 64967 | E11: =E10+C11-D11 -> 1950.25
A12: 16.09.2025 | B12: CASH DEPOSIT | C12: 250000 | E12: =E11+C12-D12 -> 251950.25
A13: 16.09.2025 | B13: FUND RECD FROM Y A X A TRADING LLC | C13: 498206 | E13: =E12+C13-D13 -> 750156.25
A14: 16.09.2025 | B14: TT TRF TO ROYAL ENBD | D14: 498504 | E14: =E13+C14-D14 -> 251652.25
A15: 16.09.2025 | B15: TT TRF TO ROYAL ENBD | D15: 248931 | E15: =E14+C15-D15 -> 2721.25
A16: 17.09.2025 | B16: CHEQUE DEPOSIT Y A X A TRADING LLC | C16: 1800000 | E16: =E15+C16-D16 -> 1802721.2
A17: 17.09.2025 | B17: TT TRF TO ROYAL ENBD | D17: 498995 | E17: =E16+C17-D17 -> 1303726.2
A18: 17.09.2025 | B18: TT TRF TO ROYAL ENBD | D18: 499572 | E18: =E17+C18-D18 -> 804154.25
A19: 17.09.2025 | B19: TT TRF TO AGNIRA WIO AED | D19: 499680 | E19: =E18+C19-D19 -> 304474.25
A20: 17.09.2025 | B20: TT TRF TO ROYAL ENBD | D20: 301251 | E20: =E19+C20-D20 -> 3223.25
A21: 18.09.2025 | B21: FUND RECD FROM SHRIJI INT EIB | C21: 499950 | E21: =E20+C21-D21 -> 503173.25
A22: 18.09.2025 | B22: TT TRF TO ROYAL ENBD | D22: 498571 | E22: =E21+C22-D22 -> 4602.25
A23: 18.09.2025 | B23: BANK CHARGES | D23: 2.1 | E23: =E22+C23-D23 -> 4600.15
A24: 18.09.2025 | B24: FUND RECD FROM AGINCO MSQ | C24: 103524 | E24: =E23+C24-D24 -> 108124.15
A25: 18.09.2025 | B25: TT TRF TO ROYAL ENBD | D25: 106324 | E25: =E24+C25-D25 -> 1800.15
A26: 22.09.2025 | B26: FUND RECD FROM SILVER CROSS EQUIPMENT | C26: 586900 | E26: =E25+C26-D26 -> 588700.15
A27: 22.09.2025 | B27: TT TRF FROM IDEA GROVE EIB TO ROYAL ENBD | D27: 586954 | E27: =E26+C27-D27 -> 1746.15
A28: 23.09.2025 | B28: FUND RECD FROM SILVER STONE WIO | C28: 538204 | E28: =E27+C28-D28 -> 539950.15
A29: 23.09.2025 | B29: FUND RECD FROM SILVER STONE WIO | C29: 298642 | E29: =E28+C29-D29 -> 838592.15
A30: 23.09.2025 | B30: TT TRF TO AGNIRA WIO AED | D30: 499582 | E30: =E29+C30-D30 -> 339010.15
A31: 23.09.2025 | B31: TT TRF TO ROYAL ENBD | D31: 336527 | E31: =E30+C31-D31 -> 2483.15
A32: 24.09.2025 | B32: FUND RECD FROM SILVER CROSS EQUIPMENT | C32: 885692 | E32: =E31+C32-D32 -> 888175.15
A33: 24.09.2025 | B33: TT TRF TO ROYAL ENBD AED | D33: 558410 | E33: =E32+C33-D33 -> 329765.15
A34: 24.09.2025 | B34: TT TRF TO ROYAL ENBD AED | D34: 326450 | E34: =E33+C34-D34 -> 3315.15
A35: 25.09.2025 | B35: CASH DEPOSIT | C35: 235000 | E35: =E34+C35-D35 -> 238315.15
A36: 25.09.2025 | B36: TT TRF TO ROYAL ENBD AED | D36: 110362 | E36: =E35+C36-D36 -> 127953.15
A37: 25.09.2025 | B37: TT TRF TO AGNIRA EIB AED | D37: 125254 | E37: =E36+C37-D37 -> 2699.15
A38: 29.09.2025 | B38: CASH DEPOSIT | C38: 149000 | E38: =E37+C38-D38 -> 151699.15
A39: 29.09.2025 | B39: CASH DEPOSIT | C39: 69000 | E39: =E38+C39-D39 -> 220699.15
A40: 29.09.2025 | B40: FUND RECD FROM RED STONE WIO AED | C40: 201309 | E40: =E39+C40-D40 -> 422008.15
A41: 29.09.2025 | B41: CASH DEPOSIT | C41: 101000 | E41: =E40+C41-D41 -> 523008.15
...

Sheet IDEA GROVE RAK AED
A1: IDEA GROVE RAK AED
A3: DATE | B3: PARTICULAR | C3: DEPOSIT | D3: WITHDRAWAL | E3: BALANCE
A5: 03.12.2025 | B5: FUND RECD FROM IDEA GROVE EIB AED | C5: 5000 | E5: =E4+C5-D5 -> 5000
A6: 04.12.2025 | B6: BANK CHARGES | D6: 103.95 | E6: =E5+C6-D6 -> 4896.05
A7: 04.12.2025 | B7: BANK CHARGES | D7: 52.5 | E7: =E6+C7-D7 -> 4843.55
A8: 04.12.2025 | B8: BANK CHARGES | D8: 103.95 | E8: =E7+C8-D8 -> 4739.6
A9: 04.12.2025 | B9: BANK CHARGES | D9: 52.5 | E9: =E8+C9-D9 -> 4687.1
A10: 04.12.2025 | B10: BANK CHARGES | D10: 103.95 | E10: =E9+C10-D10 -> 4583.15
A11: 04.12.2025 | B11: BANK CHARGES | D11: 52.5 | E11: =E10+C11-D11 -> 4530.65
A12: 04.12.2025 | B12: BANK CHARGES | D12: 52.5 | E12: =E11+C12-D12 -> 4478.15
A13: 04.12.2025 | B13: BANK CHARGES | D13: 156.45 | E13: =E12+C13-D13 -> 4321.7
A14: 22.12.2025 | B14: TT TRF TO ROYAL EN EM NBF AED | D14: 3960 | E14: =E13+C14-D14 -> 361.7
A15: 22.12.2025 | B15: BANK CHARGES | D15: 1.05 | E15: =E14+C15-D15 -> 360.65
A16: 02.01.2026 | B16: BANK CHARGES | D16: 103.95 | E16: =E15+C16-D16 -> 256.7
A17: 26.01.2026 | B17: BANK CHARGES | D17: 156.2 | E17: =E16+C17-D17 -> 100.5
A18: 27.01.2026 | B18: FUND RECD FROM IDEA GROVE EIB AED | C18: 18000 | E18: =E17+C18-D18 -> 18100.5
A19: 02.02.2026 | B19: BANK CHARGES | D19: 103.95 | E19: =E18+C19-D19 -> 17996.55
A20: 24.02.2026 | B20: CHQ PAID TO DUBAI INVESTMENT | D20: 17565 | E20: =E19+C20-D20 -> 431.55
A21: 31.03.2026 | B21: FUND RECD FROM BLACK PEPPER GT NBF AED | C21: 16800 | E21: =E20+C21-D21 -> 17231.55
A22: 31.03.2026 | B22: BANK CHARGES | D22: 156.45 | E22: =E21+C22-D22 -> 17075.1
A23: 31.03.2026 | B23: BANK CHARGES | D23: 103.95 | E23: =E22+C23-D23 -> 16971.15
A24: 31.03.2026 | B24: BANK CHARGES | D24: 156.45 | E24: =E23+C24-D24 -> 16814.7
A25: 01.04.2026 | B25: CHQ PAID TO DUBAI INVESTMENT | D25: 16250 | E25: =E24+C25-D25 -> 564.7
A26: 01.04.2026 | B26: BANK CHARGES | D26: 103.95 | E26: =E25+C26-D26 -> 460.75
A27: 01.05.2026 | B27: BANK CHARGES | D27: 103.95 | E27: =E26+C27-D27 -> 356.8
A28: 01.05.2026 | B28: BANK CHARGES | D28: 156.45 | E28: =E27+C28-D28 -> 200.35
A29: 05.05.2026 | B29: FUND RECD FROM INFINITY FORTUNE NBF AED | C29: 9050 | E29: =E28+C29-D29 -> 9250.35
E30: =E29+C30-D30 -> 9250.35
E31: =E30+C31-D31 -> 9250.35
E32: =E31+C32-D32 -> 9250.35
E33: =E32+C33-D33 -> 9250.35
E34: =E33+C34-D34 -> 9250.35
E35: =E34+C35-D35 -> 9250.35
E36: =E35+C36-D36 -> 9250.35
E37: =E36+C37-D37 -> 9250.35
E38: =E37+C38-D38 -> 9250.35
E39: =E38+C39-D39 -> 9250.35
E40: =E39+C40-D40 -> 9250.35
E41: =E40+C41-D41 -> 9250.35
... E145: =E144+C145-D145 -> 9250.35
...

Sheet IDEA GROVE SIB AED
A1: IDEA GROVE SIB AED
A3: DATE | B3: PARTICULAR | C3: DEPOSIT | D3: WITHDRAWAL | E3: BALANCE
A5: 06.03.2026 | B5: FUND RECD | C5: 5000 | E5: =E4+C5-D5 -> 5000
A6: 06.04.2026 | B6: BANK CHARGES | D6: 210 | E6: =E5+C6-D6 -> 4790
A7: 08.04.2026 | B7: FTA | D7: 70.67 | E7: =E6+C7-D7 -> 4719.33
A8: 08.04.2026 | B8: FUND RECD FROM INVESTRADE PTE LTD | C8: 548425 | E8: =E7+C8-D8 -> 553144.33
A9: 08.04.2026 | B9: BANK CHARGES | D9: 1.05 | E9: =E8+C9-D9 -> 553143.28
A10: 08.04.2026 | B10: TT TRF TO ASHIEAT AISHAMS GT NBF AED | D10: 365000 | E10: =E9+C10-D10 -> 188143.28
A11: 08.04.2026 | B11: BANK CHARGES | D11: 1.05 | E11: =E10+C11-D11 -> 188142.23
A12: 08.04.2026 | B12: TT TRF TO AMINEX SIB AED | D12: 187056 | E12: =E11+C12-D12 -> 1086.23
A13: 09.04.2026 | B13: FUND RECD FROM INVESTRADE PTE LTD | C13: 182595 | E13: =E12+C13-D13 -> 183681.23
A14: 09.04.2026 | B14: FUND RECD FROM ORBIT PLUS SIB | C14: 328500 | E14: =E13+C14-D14 -> 512181.23
A15: 09.04.2026 | B15: TT TRF TO SWIFT BRIDGE SIB AED | D15: 511046 | E15: =E14+C15-D15 -> 1135.23
A16: 09.04.2026 | B16: TT TRF TO SWIFT BRIDGE SIB AED | D16: 1000 | E16: =E15+C16-D16 -> 135.23
A17: 10.04.2026 | B17: CASH DEPOSIT | C17: 200000 | E17: =E16+C17-D17 -> 200135.23
A18: 10.04.2026 | B18: TT TRF TO SWIFT BRIDGE SIB AED | D18: 199546 | E18: =E17+C18-D18 -> 589.23
A19: 23.04.2026 | B19: FUND RECD FROM INVESTRADE PTE LTD | C19: 315285 | E19: =E18+C19-D19 -> 315874.23
A20: 23.04.2026 | B20: FUND RECD FROM AMINEX SIB | C20: 584203 | E20: =E19+C20-D20 -> 900077.23
A21: 23.04.2026 | B21: TT TRF TO SWIFT BRIDGE SIB AED | D21: 735790 | E21: =E20+C21-D21 -> 164287.23
A22: 23.04.2026 | B22: TT TRF TO ROYAL EN EM SIB AED | D22: 163520 | E22: =E21+C22-D22 -> 767.23
A23: 30.04.2026 | B23: CASH DEPOSIT | C23: 200000 | E23: =E22+C23-D23 -> 200767.23
A24: 30.04.2026 | B24: BANK CHARGES | D24: 5.25 | E24: =E23+C24-D24 -> 200761.98
A25: 30.04.2026 | B25: TT TRF TO ROYAL EN EM SIB AED | D25: 200154 | E25: =E24+C25-D25 -> 607.98
A26: 01.05.2026 | B26: BANK CHARGES | D26: 420 | E26: =E25+C26-D26 -> 187.98
E27: =E26+C27-D27 -> 187.98
E28: =E27+C28-D28 -> 187.98
E29: =E28+C29-D29 -> 187.98
E30: =E29+C30-D30 -> 187.98
E31: =E30+C31-D31 -> 187.98
E32: =E31+C32-D32 -> 187.98
E33: =E32+C33-D33 -> 187.98
E34: =E33+C34-D34 -> 187.98
E35: =E34+C35-D35 -> 187.98
E36: =E35+C36-D36 -> 187.98
E37: =E36+C37-D37 -> 187.98
E38: =E37+C38-D38 -> 187.98
... E100: =E99+C100-D100 -> 187.98

Sheet FUTURE BRIDGE MSQ AED
A1: FUTURE BRIDGE MSQ AED
A2: MSQ BANK AED
A3: DATE | B3: PARTICULAR | C3: DEPOSIT | D3: WITHDRAWAL | E3: BALANCE
